Workbook

Sheet Dashboard
A1: # | B1: CATEGORY | C1: SYMBOL | D1: NAME | E1: REFERENCE PRICE | F1: CURRENT PRICE | G1: SESSION CHANGE | H1: SERIES CHANGE | I1: CUSTOM % CHG (JAN 1) | J1: TREND (SERIES) | K1: STATUS
A2: 1 | B2: INDEX | C2: NIFTYBEES | D2: Nifty 50 ETF | E2: N/A | F2: N/A | G2: N/A | H2: N/A | I2: -1 | J2: =SPARKLINE('Daily Series Matrix'!C2:Z2) | K2: UNVERIFIED_REFERENCE
A3: 2 | B3: SENSEX | C3: SENSEXBETA | D3: Sensex ETF | E3: N/A | F3: N/A | G3: N/A | H3: N/A | I3: -1 | J3: =SPARKLINE('Daily Series Matrix'!C3:Z3) | K3: UNVERIFIED_REFERENCE
A4: 3 | B4: INDEX | C4: BANKBEES | D4: Bank Nifty ETF | E4: N/A | F4: N/A | G4: N/A | H4: N/A | I4: -1 | J4: =SPARKLINE('Daily Series Matrix'!C4:Z4) | K4: UNVERIFIED_REFERENCE
A5: 4 | B5: BULLION | C5: GOLDBEES | D5: Gold ETF | E5: N/A | F5: N/A | G5: N/A | H5: N/A | I5: -1 | J5: =SPARKLINE('Daily Series Matrix'!C5:Z5) | K5: UNVERIFIED_REFERENCE
A6: 5 | B6: BULLION | C6: SILVERBEES | D6: Silver ETF | E6: N/A | F6: N/A | G6: N/A | H6: N/A | I6: -1 | J6: =SPARKLINE('Daily Series Matrix'!C6:Z6) | K6: UNVERIFIED_REFERENCE
A7: 6 | B7: EQUITY | C7: POWERINDIA | D7: Power India | E7: N/A | F7: N/A | G7: N/A | H7: N/A | I7: -1 | J7: =SPARKLINE('Daily Series Matrix'!C7:Z7) | K7: UNVERIFIED_REFERENCE
A8: 7 | B8: AUTO | C8: SONACOMS | D8: NSE:SONACOMS | E8: N/A | F8: N/A | G8: N/A | H8: N/A | I8: -1 | J8: =SPARKLINE('Daily Series Matrix'!C8:Z8) | K8: UNVERIFIED_REFERENCE
A9: 8 | B9: PHARMA | C9: LAURUSLABS | D9: NSE:LAURUSLABS | E9: N/A | F9: N/A | G9: N/A | H9: N/A | I9: -1 | J9: =SPARKLINE('Daily Series Matrix'!C9:Z9) | K9: UNVERIFIED_REFERENCE
A10: 9 | B10: POWER | C10: ADANIENSOL | D10: NSE:ADANIENSOL | E10: N/A | F10: N/A | G10: N/A | H10: N/A | I10: -1 | J10: =SPARKLINE('Daily Series Matrix'!C10:Z10) | K10: UNVERIFIED_REFERENCE
A11: 10 | B11: DEFENCE | C11: BHARATFORG | D11: NSE:BHARATFORG | E11: N/A | F11: N/A | G11: N/A | H11: N/A | I11: -1 | J11: =SPARKLINE('Daily Series Matrix'!C11:Z11) | K11: UNVERIFIED_REFERENCE
A12: 11 | B12: IT | C12: OFSS | D12: NSE:OFSS | E12: N/A | F12: N/A | G12: N/A | H12: N/A | I12: -1 | J12: =SPARKLINE('Daily Series Matrix'!C12:Z12) | K12: UNVERIFIED_REFERENCE
A13: 12 | B13: DEFENCE | C13: SOLARINDS | D13: NSE:SOLARINDS | E13: N/A | F13: N/A | G13: N/A | H13: N/A | I13: -1 | J13: =SPARKLINE('Daily Series Matrix'!C13:Z13) | K13: UNVERIFIED_REFERENCE
... A75: 74 | B75: BFSI | C75: SAMMAANCAP | D75: NSE:SAMMAANCAP | E75: N/A | F75: N/A | G75: N/A | H75: N/A | I75: -1 | J75: =SPARKLINE('Daily Series Matrix'!C75:Z75) | K75: UNVERIFIED_REFERENCE
A76: 75 | B76: DEFENCE | C76: HAL | D76: NSE:HAL | E76: 4377.696 | F76: 4933.734 | G76: 0.064761905 | H76: 0.12701613 | I76: 0.12183863 | J76: =SPARKLINE('Daily Series Matrix'!C76:Z76) | K76: ACTIVE
A77: 76 | B77: BFSI | C77: SBIN | D77: NSE:SBIN | E77: 1029.441 | F77: 1085.7 | G77: 0.029962547 | H77: 0.054650048 | I77: 0.10251333 | J77: =SPARKLINE('Daily Series Matrix'!C77:Z77) | K77: ACTIVE
A78: 77 | B78: GOODS | C78: PIDILITIND | D78: NSE:PIDILITIND | E78: 1592.604 | F78: 1667.304 | G78: 0.012704174 | H78: 0.046904315 | I78: 0.13476073 | J78: =SPARKLINE('Daily Series Matrix'!C78:Z78) | K78: ACTIVE
A79: 78 | B79: BFSI | C79: NUVAMA | D79: NSE:NUVAMA | E79: 1811.7 | F79: 1673.595 | G79: -0.0026548673 | H79: -0.076229508 | I79: 0.14747686 | J79: =SPARKLINE('Daily Series Matrix'!C79:Z79) | K79: ACTIVE
A80: 79 | B80: FMCG | C80: PAGEIND | D80: NSE:PAGEIND | E80: 41472 | F80: 39888 | G80: -0.00090171326 | H80: -0.038194444 | I80: 0.11903493 | J80: =SPARKLINE('Daily Series Matrix'!C80:Z80) | K80: ACTIVE
A81: 80 | B81: METAL | C81: JSWSTEEL | D81: NSE:JSWSTEEL | E81: 1229.428 | F81: 1305.608 | G81: -0.018502203 | H81: 0.061963775 | I81: 0.11447546 | J81: =SPARKLINE('Daily Series Matrix'!C81:Z81) | K81: ACTIVE
A82: 81 | B82: BFSI | C82: PAYTM | D82: NSE:PAYTM | E82: 1148.824 | F82: 1444.832 | G82: 0.0091074681 | H82: 0.25766175 | I82: 0.11855079 | J82: =SPARKLINE('Daily Series Matrix'!C82:Z82) | K82: ACTIVE
A83: 82 | B83: FMCG | C83: PGEL | D83: NSE:PGEL | E83: 534.302 | F83: 605.85 | G83: -0.016853933 | H83: 0.13390929 | I83: 0.046463403 | J83: =SPARKLINE('Daily Series Matrix'!C83:Z83) | K83: ACTIVE
A84: 83 | B84: BFSI | C84: CHOLAFIN | D84: NSE:CHOLAFIN | E84: 1796.937 | F84: 1940.829 | G84: 0.031876138 | H84: 0.080076263 | I84: 0.12577088 | J84: =SPARKLINE('Daily Series Matrix'!C84:Z84) | K84: ACTIVE
A85: 84 | B85: AUTO | C85: EICHERMOT | D85: NSE:EICHERMOT | E85: 7098.344 | F85: 7934.306 | G85: -0.0073394495 | H85: 0.1177686 | I85: 0.079791236 | J85: =SPARKLINE('Daily Series Matrix'!C85:Z85) | K85: ACTIVE
A86: 85 | B86: BFSI | C86: BAJFINANCE | D86: NSE:BAJFINANCE | E86: 1007.895 | F86: 1152.873 | G86: -0.0008605852 | H86: 0.14384236 | I86: 0.1847426 | J86: =SPARKLINE('Daily Series Matrix'!C86:Z86) | K86: ACTIVE
A87: 86 | B87: PHARMA | C87: BIOCON | D87: NSE:BIOCON | E87: 418.176 | F87: 437.184 | G87: 0.026976744 | H87: 0.045454545 | I87: 0.12748936 | J87: =SPARKLINE('Daily Series Matrix'!C87:Z87) | K87: ACTIVE
... A110: 109 | B110: POWER | C110: POWERGRID | D110: NSE:POWERGRID | E110: 285.935 | F110: 270.3 | G110: -0.039548023 | H110: -0.054680259 | I110: 0.013118487 | J110: =SPARKLINE('Daily Series Matrix'!C110:Z110) | K110: ACTIVE
A111: 110 | B111: PHARMA | C111: ALKEM | D111: NSE:ALKEM | E111: 5598.16 | F111: 5598.16 | G111: -0.010710808 | H111: N/A | I111: 0.024647204 | J111: =SPARKLINE('Daily Series Matrix'!C111:Z111) | K111: ACTIVE
A112: 111 | B112: METAL | C112: NMDC | D112: NSE:NMDC | E112: 84.826 | F112: 85.324 | G112: 0.00097370983 | H112: 0.0058708415 | I112: 0.019889986 | J112: =SPARKLINE('Daily Series Matrix'!C112:Z112) | K112: ACTIVE
A113: 112 | B113: BFSI | C113: RECLTD | D113: NSE:RECLTD | E113: 363.308 | F113: 363.667 | G113: -0.0058881256 | H113: 0.00098814229 | I113: -0.010968213 | J113: =SPARKLINE('Daily Series Matrix'!C113:Z113) | K113: ACTIVE
A114: 113 | B114: REALITY | C114: APLAPOLLO | D114: NSE:APLAPOLLO | E114: 1792.11 | F114: 1955.905 | G114: -0.0019665683 | H114: 0.091397849 | I114: -0.0071548223 | J114: =SPARKLINE('Daily Series Matrix'!C114:Z114) | K114: ACTIVE
A115: 114 | B115: GENERAL | C115: GMRAIRPORT | D115: NSE:GMRAIRPORT | E115: 112.875 | F115: 106.155 | G115: -0.0068762279 | H115: -0.059534884 | I115: 0.0062085308 | J115: =SPARKLINE('Daily Series Matrix'!C115:Z115) | K115: ACTIVE
A116: 115 | B116: PHARMA | C116: MAXHEALTH | D116: NSE:MAXHEALTH | E116: 1128.75 | F116: 1066.8 | G116: -0.0068426197 | H116: -0.054883721 | I116: 0.01658088 | J116: =SPARKLINE('Daily Series Matrix'!C116:Z116) | K116: ACTIVE
A117: 116 | B117: REALITY | C117: PHOENIXLTD | D117: NSE:PHOENIXLTD | E117: 1963.602 | F117: 1913.301 | G117: -0.0077294686 | H117: -0.025616698 | I117: 0.021680488 | J117: =SPARKLINE('Daily Series Matrix'!C117:Z117) | K117: ACTIVE
A118: 117 | B118: CEMENT | C118: ULTRACEMCO | D118: NSE:ULTRACEMCO | E118: 11284.566 | F118: 12103.32 | G118: -0.0068159688 | H118: 0.072555205 | I118: 0.017000252 | J118: =SPARKLINE('Daily Series Matrix'!C118:Z118) | K118: ACTIVE
A119: 118 | B119: GOODS | C119: SUPREMEIND | D119: NSE:SUPREMEIND | E119: 3156.92 | F119: 3450.98 | G119: -0.0048732943 | H119: 0.093147752 | I119: -0.0095912936 | J119: =SPARKLINE('Daily Series Matrix'!C119:Z119) | K119: ACTIVE
A120: 119 | B120: BFSI | C120: IIFL | D120: NSE:IIFL | E120: 505.725 | F120: 609.935 | G120: 0.0030241935 | H120: 0.20606061 | I120: -0.016947396 | J120: =SPARKLINE('Daily Series Matrix'!C120:Z120) | K120: ACTIVE
A121: 120 | B121: DEFENCE | C121: MAZDOCK | D121: NSE:MAZDOCK | E121: 2486.472 | F121: 2531.544 | G121: 0.065331928 | H121: 0.018126888 | I121: 0.022144002 | J121: =SPARKLINE('Daily Series Matrix'!C121:Z121) | K121: ACTIVE
A122: 121 | B122: DEFENCE | C122: BEL | D122: NSE:BEL | E122: 412.452 | F122: 399.186 | G122: 0.024767802 | H122: -0.032163743 | I122: 0.003736454 | J122: =SPARKLINE('Daily Series Matrix'!C122:Z122) | K122: ACTIVE
A123: 122 | B123: AUTO | C123: ASHOKLEY | D123: NSE:ASHOKLEY | E123: 157.707 | F123: 177.354 | G123: 0.0090634441 | H123: 0.12457912 | I123: -0.040707511 | J123: =SPARKLINE('Daily Series Matrix'!C123:Z123) | K123: ACTIVE
...

Sheet Daily Series Matrix
A1: SYMBOL | B1: REF PRICE | C1: 29-Jul | D1: 30-Jul | E1: 31-Jul | F1: 03-Aug | G1: 04-Aug | H1: 05-Aug | I1: 06-Aug | J1: 07-Aug
A2: NIFTYBEES | B2: N/A | C2: 0.0083720563 | D2: 0.010821451 | E2: 0.014221528 | F2: 0.023178431 | G2: 0.019230102 | H2: 0.02350745 | I2: 0.025810688 | J2: 0.023032164
A3: SENSEXBETA | B3: N/A | C3: 0.0064950402 | D3: 0.016426588 | E3: 0.0194733 | F3: 0.020831383 | G3: 0.024586688 | H3: 0.025389703 | I3: 0.020004727 | J3: 0.0281649
A4: BANKBEES | B4: N/A | C4: 0.0071484705 | D4: 0.0060251884 | E4: 0.0080335499 | F4: 0.016679799 | G4: 0.013990591 | H4: 0.014926677 | I4: 0.021479381 | J4: 0.0191307
A5: GOLDBEES | B5: N/A | C5: 0.00017116017 | D5: 0.0046221083 | E5: 0.0023966342 | F5: 0.0036805641 | G5: 0.0027390199 | H5: 0.021912159 | I5: 0.048360879 | J5: 0.056235552
A6: SILVERBEES | B6: N/A | C6: 0.0023763603 | D6: 0.0020853925 | E6: 0.0015033829 | F6: 0.0012124151 | G6: 0.0055771541 | H6: 0.034869072 | I6: 0.040397682 | J6: 0.069204677
A7: POWERINDIA | B7: N/A | C7: 0.017507228 | D7: 0.0038548024 | E7: 0.033568905 | F7: 0.027947318 | G7: 0.028107934 | H7: 0.040796659 | I7: 0.024734982 | J7: 0.04722133
A8: SONACOMS | B8: N/A | C8: MISSING | D8: MISSING | E8: MISSING | F8: MISSING | G8: MISSING | H8: MISSING | I8: MISSING | J8: MISSING
A9: LAURUSLABS | B9: N/A | C9: MISSING | D9: MISSING | E9: MISSING | F9: MISSING | G9: MISSING | H9: MISSING | I9: MISSING | J9: MISSING
A10: ADANIENSOL | B10: N/A | C10: MISSING | D10: MISSING | E10: MISSING | F10: MISSING | G10: MISSING | H10: MISSING | I10: MISSING | J10: MISSING
A11: BHARATFORG | B11: N/A | C11: MISSING | D11: MISSING | E11: MISSING | F11: MISSING | G11: MISSING | H11: MISSING | I11: MISSING | J11: MISSING
A12: OFSS | B12: N/A | C12: MISSING | D12: MISSING | E12: MISSING | F12: MISSING | G12: MISSING | H12: MISSING | I12: MISSING | J12: MISSING
A13: SOLARINDS | B13: N/A | C13: MISSING | D13: MISSING | E13: MISSING | F13: MISSING | G13: MISSING | H13: MISSING | I13: MISSING | J13: MISSING
A14: ABB | B14: N/A | C14: MISSING | D14: MISSING | E14: MISSING | F14: MISSING | G14: MISSING | H14: MISSING | I14: MISSING | J14: MISSING
A15: ADANIPOWER | B15: N/A | C15: MISSING | D15: MISSING | E15: MISSING | F15: MISSING | G15: MISSING | H15: MISSING | I15: MISSING | J15: MISSING
A16: MOTHERSON | B16: N/A | C16: MISSING | D16: MISSING | E16: MISSING | F16: MISSING | G16: MISSING | H16: MISSING | I16: MISSING | J16: MISSING
A17: RADICO | B17: N/A | C17: MISSING | D17: MISSING | E17: MISSING | F17: MISSING | G17: MISSING | H17: MISSING | I17: MISSING | J17: MISSING
A18: AUROPHARMA | B18: N/A | C18: MISSING | D18: MISSING | E18: MISSING | F18: MISSING | G18: MISSING | H18: MISSING | I18: MISSING | J18: MISSING
A19: BHEL | B19: N/A | C19: MISSING | D19: MISSING | E19: MISSING | F19: MISSING | G19: MISSING | H19: MISSING | I19: MISSING | J19: MISSING
... A75: SAMMAANCAP | B75: N/A | C75: MISSING | D75: MISSING | E75: MISSING | F75: MISSING | G75: MISSING | H75: MISSING | I75: MISSING | J75: MISSING
A76: HAL | B76: 4377.696 | C76: MISSING | D76: MISSING | E76: MISSING | F76: MISSING | G76: MISSING | H76: MISSING | I76: MISSING | J76: MISSING
A77: SBIN | B77: 1029.441 | C77: MISSING | D77: MISSING | E77: MISSING | F77: MISSING | G77: MISSING | H77: MISSING | I77: MISSING | J77: MISSING
A78: PIDILITIND | B78: 1592.604 | C78: MISSING | D78: MISSING | E78: MISSING | F78: MISSING | G78: MISSING | H78: MISSING | I78: MISSING | J78: MISSING
A79: NUVAMA | B79: 1811.7 | C79: MISSING | D79: MISSING | E79: MISSING | F79: MISSING | G79: MISSING | H79: MISSING | I79: MISSING | J79: MISSING
A80: PAGEIND | B80: 41472 | C80: MISSING | D80: MISSING | E80: MISSING | F80: MISSING | G80: MISSING | H80: MISSING | I80: MISSING | J80: MISSING
A81: JSWSTEEL | B81: 1229.428 | C81: MISSING | D81: MISSING | E81: MISSING | F81: MISSING | G81: MISSING | H81: MISSING | I81: MISSING | J81: MISSING
A82: PAYTM | B82: 1148.824 | C82: MISSING | D82: MISSING | E82: MISSING | F82: MISSING | G82: MISSING | H82: MISSING | I82: MISSING | J82: MISSING
A83: PGEL | B83: 534.302 | C83: MISSING | D83: MISSING | E83: MISSING | F83: MISSING | G83: MISSING | H83: MISSING | I83: MISSING | J83: MISSING
A84: CHOLAFIN | B84: 1796.937 | C84: MISSING | D84: MISSING | E84: MISSING | F84: MISSING | G84: MISSING | H84: MISSING | I84: MISSING | J84: MISSING
A85: EICHERMOT | B85: 7098.344 | C85: MISSING | D85: MISSING | E85: MISSING | F85: MISSING | G85: MISSING | H85: MISSING | I85: MISSING | J85: MISSING
A86: BAJFINANCE | B86: 1007.895 | C86: MISSING | D86: MISSING | E86: MISSING | F86: MISSING | G86: MISSING | H86: MISSING | I86: MISSING | J86: MISSING
A87: BIOCON | B87: 418.176 | C87: MISSING | D87: MISSING | E87: MISSING | F87: MISSING | G87: MISSING | H87: MISSING | I87: MISSING | J87: MISSING
... A223: KPITTECH | B223: 670.956 | C223: MISSING | D223: MISSING | E223: MISSING | F223: MISSING | G223: MISSING | H223: MISSING | I223: MISSING | J223: MISSING

Sheet Daily Session Matrix
A1: SYMBOL | B1: REF PRICE | C1: 29-Jul | D1: 30-Jul | E1: 31-Jul | F1: 03-Aug | G1: 04-Aug | H1: 05-Aug | I1: 06-Aug | J1: 07-Aug
A2: NIFTYBEES | B2: N/A | C2: 0.0083720563 | D2: 0.0024290584 | E2: 0.0033636776 | F2: 0.0088313084 | G2: -0.0038588866 | H2: 0.0041966458 | I2: 0.002250339 | J2: -0.0027725989
A3: SENSEXBETA | B3: N/A | C3: 0.0064950402 | D3: 0.0098674578 | E3: 0.0029974742 | F3: 0.0013321415 | G3: 0.0036786737 | H3: 0.00078374482 | I3: -0.0052516384 | J3: 0.0089112177
A4: BANKBEES | B4: N/A | C4: 0.0071484705 | D4: -0.0011153094 | E4: 0.0019963332 | F4: 0.0085773427 | G4: -0.0026450883 | H4: 0.00092317004 | I4: 0.0064563324 | J4: -0.0014091652
A5: GOLDBEES | B5: N/A | C5: 0.00017116017 | D5: 0.0044501864 | E5: -0.002215235 | F5: 0.0012808601 | G5: -0.00093809149 | H5: 0.019120767 | I5: 0.025881598 | J5: 0.008812818
A6: SILVERBEES | B6: N/A | C6: 0.0023763603 | D6: -0.00029027799 | E6: -0.0005807984 | F6: -0.00029053102 | G6: 0.0043594535 | H6: 0.029129458 | I6: 0.0053423281 | J6: 0.027688447
A7: POWERINDIA | B7: N/A | C7: 0.017507228 | D7: -0.013417522 | E7: 0.0296 | F7: -0.0054390054 | G7: 0.00015625 | H7: 0.012341822 | I7: -0.015432099 | J7: 0.019317951
A8: SONACOMS | B8: N/A | C8: MISSING | D8: MISSING | E8: MISSING | F8: MISSING | G8: MISSING | H8: MISSING | I8: MISSING | J8: MISSING
A9: LAURUSLABS | B9: N/A | C9: MISSING | D9: MISSING | E9: MISSING | F9: MISSING | G9: MISSING | H9: MISSING | I9: MISSING | J9: MISSING
A10: ADANIENSOL | B10: N/A | C10: MISSING | D10: MISSING | E10: MISSING | F10: MISSING | G10: MISSING | H10: MISSING | I10: MISSING | J10: MISSING
A11: BHARATFORG | B11: N/A | C11: MISSING | D11: MISSING | E11: MISSING | F11: MISSING | G11: MISSING | H11: MISSING | I11: MISSING | J11: MISSING
A12: OFSS | B12: N/A | C12: MISSING | D12: MISSING | E12: MISSING | F12: MISSING | G12: MISSING | H12: MISSING | I12: MISSING | J12: MISSING
A13: SOLARINDS | B13: N/A | C13: MISSING | D13: MISSING | E13: MISSING | F13: MISSING | G13: MISSING | H13: MISSING | I13: MISSING | J13: MISSING
A14: ABB | B14: N/A | C14: MISSING | D14: MISSING | E14: MISSING | F14: MISSING | G14: MISSING | H14: MISSING | I14: MISSING | J14: MISSING
A15: ADANIPOWER | B15: N/A | C15: MISSING | D15: MISSING | E15: MISSING | F15: MISSING | G15: MISSING | H15: MISSING | I15: MISSING | J15: MISSING
A16: MOTHERSON | B16: N/A | C16: MISSING | D16: MISSING | E16: MISSING | F16: MISSING | G16: MISSING | H16: MISSING | I16: MISSING | J16: MISSING
A17: RADICO | B17: N/A | C17: MISSING | D17: MISSING | E17: MISSING | F17: MISSING | G17: MISSING | H17: MISSING | I17: MISSING | J17: MISSING
A18: AUROPHARMA | B18: N/A | C18: MISSING | D18: MISSING | E18: MISSING | F18: MISSING | G18: MISSING | H18: MISSING | I18: MISSING | J18: MISSING
A19: BHEL | B19: N/A | C19: MISSING | D19: MISSING | E19: MISSING | F19: MISSING | G19: MISSING | H19: MISSING | I19: MISSING | J19: MISSING
... A75: SAMMAANCAP | B75: N/A | C75: MISSING | D75: MISSING | E75: MISSING | F75: MISSING | G75: MISSING | H75: MISSING | I75: MISSING | J75: MISSING
A76: HAL | B76: 4377.696 | C76: MISSING | D76: MISSING | E76: MISSING | F76: MISSING | G76: MISSING | H76: MISSING | I76: MISSING | J76: MISSING
A77: SBIN | B77: 1029.441 | C77: MISSING | D77: MISSING | E77: MISSING | F77: MISSING | G77: MISSING | H77: MISSING | I77: MISSING | J77: MISSING
A78: PIDILITIND | B78: 1592.604 | C78: MISSING | D78: MISSING | E78: MISSING | F78: MISSING | G78: MISSING | H78: MISSING | I78: MISSING | J78: MISSING
A79: NUVAMA | B79: 1811.7 | C79: MISSING | D79: MISSING | E79: MISSING | F79: MISSING | G79: MISSING | H79: MISSING | I79: MISSING | J79: MISSING
A80: PAGEIND | B80: 41472 | C80: MISSING | D80: MISSING | E80: MISSING | F80: MISSING | G80: MISSING | H80: MISSING | I80: MISSING | J80: MISSING
A81: JSWSTEEL | B81: 1229.428 | C81: MISSING | D81: MISSING | E81: MISSING | F81: MISSING | G81: MISSING | H81: MISSING | I81: MISSING | J81: MISSING
A82: PAYTM | B82: 1148.824 | C82: MISSING | D82: MISSING | E82: MISSING | F82: MISSING | G82: MISSING | H82: MISSING | I82: MISSING | J82: MISSING
A83: PGEL | B83: 534.302 | C83: MISSING | D83: MISSING | E83: MISSING | F83: MISSING | G83: MISSING | H83: MISSING | I83: MISSING | J83: MISSING
A84: CHOLAFIN | B84: 1796.937 | C84: MISSING | D84: MISSING | E84: MISSING | F84: MISSING | G84: MISSING | H84: MISSING | I84: MISSING | J84: MISSING
A85: EICHERMOT | B85: 7098.344 | C85: MISSING | D85: MISSING | E85: MISSING | F85: MISSING | G85: MISSING | H85: MISSING | I85: MISSING | J85: MISSING
A86: BAJFINANCE | B86: 1007.895 | C86: MISSING | D86: MISSING | E86: MISSING | F86: MISSING | G86: MISSING | H86: MISSING | I86: MISSING | J86: MISSING
A87: BIOCON | B87: 418.176 | C87: MISSING | D87: MISSING | E87: MISSING | F87: MISSING | G87: MISSING | H87: MISSING | I87: MISSING | J87: MISSING
... A223: KPITTECH | B223: 670.956 | C223: MISSING | D223: MISSING | E223: MISSING | F223: MISSING | G223: MISSING | H223: MISSING | I223: MISSING | J223: MISSING
